Workbook

Sheet Subscriptions
A1: CustomerID | B1: Age | C1: Gender | D1: SubscriptionStart | E1: SubscriptionEnd | F1: DurationDays | G1: MonthsPaid | H1: SubType | I1: Tier | J1: Monthly | K1: Discounted | L1: TotalRevenue | M1: AgeGroup | N1: Region | O1: ReferralSource | P1: CancellationReason | Q1: RevenueCategory | R1: AgeBracket | S1: ChurnStatus | T1: LifetimeValue | U1: CancellationDate | V1: NextBillingDate | W1: ContractEndDate | X1: RenewalCount | Y1: EffectiveEndDate | Z1: ActiveFlagToday | AA1: ActiveOn_AsOfDate1 | AB1: ActiveOn_AsOfDate2 | AC1: ActiveOn_AsOfDate3 | AD1: ActiveOn_AsOfDate4 | AE1: ActiveOn_AsOfDate5
A2: CUST0246 | B2: 50 | C2: Male | D2: 44562 | E2: 44742 | F2: =TODAY() - Table1[[#This Row],[SubscriptionStart]] -> 1419 | G2: 6 | H2: 6-Month | I2: Standard | J2: {=_xlfn.IFS(Table1[[#This Row],[Tier]]="Basic",10,Table1[[#This Row],[Tier]]="Standard",18,Table1[[#This Row],[Tier]]="Premium",25)} -> 18 | K2: {=_xlfn.IFS(Table1[[#This Row],[SubType]]="Monthly",IF(Table1[[#This Row],[MonthsPaid]]<=12,Table1[[#This Row],[Monthly]]*0.9,Table1[[#This Row],[Monthly]]),Table1[[#This Row],[SubType]]="6-Month",IF(Table1[[#This Row],[MonthsPaid]]<=12,Table1[[#This Row],[Monthly]]*0.75*0.9,Table1[[#This Row],[Monthly]]*0.75),Table1[[#This Row],[SubType]]="12-Month",IF(Table1[[#This Row],[MonthsPaid]]<=12,Table1[[#This Row],[Monthly]]*(2/3)*0.9,Table1[[#This Row],[Monthly]]*(2/3)))} -> 12.15 | L2: {=ROUND(_xlfn.IFS(Table1[[#This Row],[SubType]]="Monthly",(MAX(MIN(Table1[[#This Row],[MonthsPaid]],12)-1,0)*Table1[[#This Row],[Monthly]]*0.9)+(MAX(Table1[[#This Row],[MonthsPaid]]-12,0)*Table1[[#This Row],[Monthly]]),Table1[[#This Row],[SubType]]="6-Month",(MIN(Table1[[#This Row],[MonthsPaid]],12)*Table1[[#This Row],[Monthly]]*0.75*0.9)+(MAX(Table1[[#This Row],[MonthsPaid]]-12,0)*Table1[[#This Row],[Monthly]]*0.75),Table1[[#This Row],[SubType]]="12-Month",(MIN(Table1[[#This Row],[MonthsPaid]],12)*Table1[[#This Row],[Monthly]]*(2/3)*0.9)+(MAX(Table1[[#This Row],[MonthsPaid]]-12,0)*Table1[[#This Row],[Monthly]]*(2/3))),2)} -> 72.9 | M2: {=_xlfn.IFS(Table1[[#This Row],[Age]]>70,"Elderly",Table1[[#This Row],[Age]]>59,"Senior",Table1[[#This Row],[Age]]>49,"Mature Adult",Table1[[#This Row],[Age]]>25,"Adult",Table1[[#This Row],[Age]]>=18,"Young Adult")} -> Mature Adult | N2: Scotland | O2: None | P2: Poor Experience | Q2: {=_xlfn.IFS(Table1[[#This Row],[TotalRevenue]]<100,"Low",Table1[[#This Row],[TotalRevenue]]<300,"Medium",Table1[[#This Row],[TotalRevenue]]<600,"High",TRUE,"Very High")} -> Low | R2: {=_xlfn.IFS(Table1[[#This Row],[Age]]>69,"Elderly",Table1[[#This Row],[Age]]>59,"Mature Adult",Table1[[#This Row],[Age]]>25,"Adult",Table1[[#This Row],[Age]]>18,"Young Adult",Table1[[#This Row],[Age]]>=12,"Teenager")} -> Adult | S2: =IF(Table1[[#This Row],[NextBillingDate]]="","Cancelled",IF(Table1[[#This Row],[CancellationDate]]<>"","Cancelled","Active")) -> Cancelled | T2: {=IF(Table1[[#This Row],[ChurnStatus]]="Cancelled",Table1[[#This Row],[TotalRevenue]],Table1[[#This Row],[TotalRevenue]] + Table1[[#This Row],[Discounted]] * _xlfn.IFS(Table1[[#This Row],[SubType]]="Monthly",1,Table1[[#This Row],[SubType]]="6-Month",6-MOD(Table1[[#This Row],[MonthsPaid]],6),Table1[[#This Row],[SubType]]="12-Month",12-MOD(Table1[[#This Row],[MonthsPaid]],12)))} -> 72.9 | U2: 44742 | W2: 44742 | X2: 0 | Y2: =IF(Table1[[#This Row],[ChurnStatus]]="Cancelled",Table1[[#This Row],[CancellationDate]],TODAY()) -> 44742 | Z2: =IF(AND(Table1[[#This Row],[SubscriptionStart]] <= TODAY(), Table1[[#This Row],[EffectiveEndDate]] >= TODAY()),1,0) -> 0 | AA2: =IF(AND(Table1[[#This Row],[SubscriptionStart]]<=Settings!$A$2,Table1[[#This Row],[EffectiveEndDate]]>=Settings!$A$2),1,0) -> 1 | AB2: =IF(AND(Table1[[#This Row],[SubscriptionStart]]<=Settings!$B$2,Table1[[#This Row],[EffectiveEndDate]]>=Settings!$B$2),1,0) -> 1 | AC2: =IF(AND(Table1[[#This Row],[SubscriptionStart]]<=Settings!$C$2,Table1[[#This Row],[EffectiveEndDate]]>=Settings!$C$2),1,0) -> 0 | AD2: =IF(AND(Table1[[#This Row],[SubscriptionStart]]<=Settings!$D$2,Table1[[#This Row],[EffectiveEndDate]]>=Settings!$D$2),1,0) -> 0 | AE2: =IF(AND(Table1[[#This Row],[SubscriptionStart]]<=Settings!$E$2,Table1[[#This Row],[EffectiveEndDate]]>=Settings!$E$2),1,0) -> 0
A3: CUST0192 | B3: 19 | C3: Male | D3: 44562 | E3: 44922 | F3: =TODAY() - Table1[[#This Row],[SubscriptionStart]] -> 1419 | G3: 12 | H3: 12-Month | I3: Standard | J3: {=_xlfn.IFS(Table1[[#This Row],[Tier]]="Basic",10,Table1[[#This Row],[Tier]]="Standard",18,Table1[[#This Row],[Tier]]="Premium",25)} -> 18 | K3: {=_xlfn.IFS(Table1[[#This Row],[SubType]]="Monthly",IF(Table1[[#This Row],[MonthsPaid]]<=12,Table1[[#This Row],[Monthly]]*0.9,Table1[[#This Row],[Monthly]]),Table1[[#This Row],[SubType]]="6-Month",IF(Table1[[#This Row],[MonthsPaid]]<=12,Table1[[#This Row],[Monthly]]*0.75*0.9,Table1[[#This Row],[Monthly]]*0.75),Table1[[#This Row],[SubType]]="12-Month",IF(Table1[[#This Row],[MonthsPaid]]<=12,Table1[[#This Row],[Monthly]]*(2/3)*0.9,Table1[[#This Row],[Monthly]]*(2/3)))} -> 10.8 | L3: {=ROUND(_xlfn.IFS(Table1[[#This Row],[SubType]]="Monthly",(MAX(MIN(Table1[[#This Row],[MonthsPaid]],12)-1,0)*Table1[[#This Row],[Monthly]]*0.9)+(MAX(Table1[[#This Row],[MonthsPaid]]-12,0)*Table1[[#This Row],[Monthly]]),Table1[[#This Row],[SubType]]="6-Month",(MIN(Table1[[#This Row],[MonthsPaid]],12)*Table1[[#This Row],[Monthly]]*0.75*0.9)+(MAX(Table1[[#This Row],[MonthsPaid]]-12,0)*Table1[[#This Row],[Monthly]]*0.75),Table1[[#This Row],[SubType]]="12-Month",(MIN(Table1[[#This Row],[MonthsPaid]],12)*Table1[[#This Row],[Monthly]]*(2/3)*0.9)+(MAX(Table1[[#This Row],[MonthsPaid]]-12,0)*Table1[[#This Row],[Monthly]]*(2/3))),2)} -> 129.6 | M3: {=_xlfn.IFS(Table1[[#This Row],[Age]]>70,"Elderly",Table1[[#This Row],[Age]]>59,"Senior",Table1[[#This Row],[Age]]>49,"Mature Adult",Table1[[#This Row],[Age]]>25,"Adult",Table1[[#This Row],[Age]]>=18,"Young Adult")} -> Young Adult | N3: Northern Ireland | O3: Search Engine | P3: Switched Service | Q3: {=_xlfn.IFS(Table1[[#This Row],[TotalRevenue]]<100,"Low",Table1[[#This Row],[TotalRevenue]]<300,"Medium",Table1[[#This Row],[TotalRevenue]]<600,"High",TRUE,"Very High")} -> Medium | R3: {=_xlfn.IFS(Table1[[#This Row],[Age]]>69,"Elderly",Table1[[#This Row],[Age]]>59,"Mature Adult",Table1[[#This Row],[Age]]>25,"Adult",Table1[[#This Row],[Age]]>18,"Young Adult",Table1[[#This Row],[Age]]>=12,"Teenager")} -> Young Adult | S3: =IF(Table1[[#This Row],[NextBillingDate]]="","Cancelled",IF(Table1[[#This Row],[CancellationDate]]<>"","Cancelled","Active")) -> Cancelled | T3: {=IF(Table1[[#This Row],[ChurnStatus]]="Cancelled",Table1[[#This Row],[TotalRevenue]],Table1[[#This Row],[TotalRevenue]] + Table1[[#This Row],[Discounted]] * _xlfn.IFS(Table1[[#This Row],[SubType]]="Monthly",1,Table1[[#This Row],[SubType]]="6-Month",6-MOD(Table1[[#This Row],[MonthsPaid]],6),Table1[[#This Row],[SubType]]="12-Month",12-MOD(Table1[[#This Row],[MonthsPaid]],12)))} -> 129.6 | U3: 44922 | W3: 44922 | X3: 0 | Y3: =IF(Table1[[#This Row],[ChurnStatus]]="Cancelled",Table1[[#This Row],[CancellationDate]],TODAY()) -> 44922 | Z3: =IF(AND(Table1[[#This Row],[SubscriptionStart]] <= TODAY(), Table1[[#This Row],[EffectiveEndDate]] >= TODAY()),1,0) -> 0 | AA3: =IF(AND(Table1[[#This Row],[SubscriptionStart]]<=Settings!$A$2,Table1[[#This Row],[EffectiveEndDate]]>=Settings!$A$2),1,0) -> 1 | AB3: =IF(AND(Table1[[#This Row],[SubscriptionStart]]<=Settings!$B$2,Table1[[#This Row],[EffectiveEndDate]]>=Settings!$B$2),1,0) -> 1 | AC3: =IF(AND(Table1[[#This Row],[SubscriptionStart]]<=Settings!$C$2,Table1[[#This Row],[EffectiveEndDate]]>=Settings!$C$2),1,0) -> 0 | AD3: =IF(AND(Table1[[#This Row],[SubscriptionStart]]<=Settings!$D$2,Table1[[#This Row],[EffectiveEndDate]]>=Settings!$D$2),1,0) -> 0 | AE3: =IF(AND(Table1[[#This Row],[SubscriptionStart]]<=Settings!$E$2,Table1[[#This Row],[EffectiveEndDate]]>=Settings!$E$2),1,0) -> 0
A4: CUST0146 | B4: 43 | C4: Female | D4: 44562 | F4: =TODAY() - Table1[[#This Row],[SubscriptionStart]] -> 1419 | G4: 48 | H4: 6-Month | I4: Standard | J4: {=_xlfn.IFS(Table1[[#This Row],[Tier]]="Basic",10,Table1[[#This Row],[Tier]]="Standard",18,Table1[[#This Row],[Tier]]="Premium",25)} -> 18 | K4: {=_xlfn.IFS(Table1[[#This Row],[SubType]]="Monthly",IF(Table1[[#This Row],[MonthsPaid]]<=12,Table1[[#This Row],[Monthly]]*0.9,Table1[[#This Row],[Monthly]]),Table1[[#This Row],[SubType]]="6-Month",IF(Table1[[#This Row],[MonthsPaid]]<=12,Table1[[#This Row],[Monthly]]*0.75*0.9,Table1[[#This Row],[Monthly]]*0.75),Table1[[#This Row],[SubType]]="12-Month",IF(Table1[[#This Row],[MonthsPaid]]<=12,Table1[[#This Row],[Monthly]]*(2/3)*0.9,Table1[[#This Row],[Monthly]]*(2/3)))} -> 13.5 | L4: {=ROUND(_xlfn.IFS(Table1[[#This Row],[SubType]]="Monthly",(MAX(MIN(Table1[[#This Row],[MonthsPaid]],12)-1,0)*Table1[[#This Row],[Monthly]]*0.9)+(MAX(Table1[[#This Row],[MonthsPaid]]-12,0)*Table1[[#This Row],[Monthly]]),Table1[[#This Row],[SubType]]="6-Month",(MIN(Table1[[#This Row],[MonthsPaid]],12)*Table1[[#This Row],[Monthly]]*0.75*0.9)+(MAX(Table1[[#This Row],[MonthsPaid]]-12,0)*Table1[[#This Row],[Monthly]]*0.75),Table1[[#This Row],[SubType]]="12-Month",(MIN(Table1[[#This Row],[MonthsPaid]],12)*Table1[[#This Row],[Monthly]]*(2/3)*0.9)+(MAX(Table1[[#This Row],[MonthsPaid]]-12,0)*Table1[[#This Row],[Monthly]]*(2/3))),2)} -> 631.8 | M4: {=_xlfn.IFS(Table1[[#This Row],[Age]]>70,"Elderly",Table1[[#This Row],[Age]]>59,"Senior",Table1[[#This Row],[Age]]>49,"Mature Adult",Table1[[#This Row],[Age]]>25,"Adult",Table1[[#This Row],[Age]]>=18,"Young Adult")} -> Adult | N4: England | O4: Friend | Q4: {=_xlfn.IFS(Table1[[#This Row],[TotalRevenue]]<100,"Low",Table1[[#This Row],[TotalRevenue]]<300,"Medium",Table1[[#This Row],[TotalRevenue]]<600,"High",TRUE,"Very High")} -> Very High | R4: {=_xlfn.IFS(Table1[[#This Row],[Age]]>69,"Elderly",Table1[[#This Row],[Age]]>59,"Mature Adult",Table1[[#This Row],[Age]]>25,"Adult",Table1[[#This Row],[Age]]>18,"Young Adult",Table1[[#This Row],[Age]]>=12,"Teenager")} -> Adult | S4: =IF(Table1[[#This Row],[NextBillingDate]]="","Cancelled",IF(Table1[[#This Row],[CancellationDate]]<>"","Cancelled","Active")) -> Active | T4: {=IF(Table1[[#This Row],[ChurnStatus]]="Cancelled",Table1[[#This Row],[TotalRevenue]],Table1[[#This Row],[TotalRevenue]] + Table1[[#This Row],[Discounted]] * _xlfn.IFS(Table1[[#This Row],[SubType]]="Monthly",1,Table1[[#This Row],[SubType]]="6-Month",6-MOD(Table1[[#This Row],[MonthsPaid]],6),Table1[[#This Row],[SubType]]="12-Month",12-MOD(Table1[[#This Row],[MonthsPaid]],12)))} -> 712.8 | V4: 46002 | W4: 46002 | X4: 7 | Y4: =IF(Table1[[#This Row],[ChurnStatus]]="Cancelled",Table1[[#This Row],[CancellationDate]],TODAY()) -> 45981 | Z4: =IF(AND(Table1[[#This Row],[SubscriptionStart]] <= TODAY(), Table1[[#This Row],[EffectiveEndDate]] >= TODAY()),1,0) -> 1 | AA4: =IF(AND(Table1[[#This Row],[SubscriptionStart]]<=Settings!$A$2,Table1[[#This Row],[EffectiveEndDate]]>=Settings!$A$2),1,0) -> 1 | AB4: =IF(AND(Table1[[#This Row],[SubscriptionStart]]<=Settings!$B$2,Table1[[#This Row],[EffectiveEndDate]]>=Settings!$B$2),1,0) -> 1 | AC4: =IF(AND(Table1[[#This Row],[SubscriptionStart]]<=Settings!$C$2,Table1[[#This Row],[EffectiveEndDate]]>=Settings!$C$2),1,0) -> 1 | AD4: =IF(AND(Table1[[#This Row],[SubscriptionStart]]<=Settings!$D$2,Table1[[#This Row],[EffectiveEndDate]]>=Settings!$D$2),1,0) -> 1 | AE4: =IF(AND(Table1[[#This Row],[SubscriptionStart]]<=Settings!$E$2,Table1[[#This Row],[EffectiveEndDate]]>=Settings!$E$2),1,0) -> 1
A5: CUST0561 | B5: 30 | C5: Female | D5: 44563 | E5: 44923 | F5: =TODAY() - Table1[[#This Row],[SubscriptionStart]] -> 1418 | G5: 12 | H5: 12-Month | I5: Premium | J5: {=_xlfn.IFS(Table1[[#This Row],[Tier]]="Basic",10,Table1[[#This Row],[Tier]]="Standard",18,Table1[[#This Row],[Tier]]="Premium",25)} -> 25 | K5: {=_xlfn.IFS(Table1[[#This Row],[SubType]]="Monthly",IF(Table1[[#This Row],[MonthsPaid]]<=12,Table1[[#This Row],[Monthly]]*0.9,Table1[[#This Row],[Monthly]]),Table1[[#This Row],[SubType]]="6-Month",IF(Table1[[#This Row],[MonthsPaid]]<=12,Table1[[#This Row],[Monthly]]*0.75*0.9,Table1[[#This Row],[Monthly]]*0.75),Table1[[#This Row],[SubType]]="12-Month",IF(Table1[[#This Row],[MonthsPaid]]<=12,Table1[[#This Row],[Monthly]]*(2/3)*0.9,Table1[[#This Row],[Monthly]]*(2/3)))} -> 15 | L5: {=ROUND(_xlfn.IFS(Table1[[#This Row],[SubType]]="Monthly",(MAX(MIN(Table1[[#This Row],[MonthsPaid]],12)-1,0)*Table1[[#This Row],[Monthly]]*0.9)+(MAX(Table1[[#This Row],[MonthsPaid]]-12,0)*Table1[[#This Row],[Monthly]]),Table1[[#This Row],[SubType]]="6-Month",(MIN(Table1[[#This Row],[MonthsPaid]],12)*Table1[[#This Row],[Monthly]]*0.75*0.9)+(MAX(Table1[[#This Row],[MonthsPaid]]-12,0)*Table1[[#This Row],[Monthly]]*0.75),Table1[[#This Row],[SubType]]="12-Month",(MIN(Table1[[#This Row],[MonthsPaid]],12)*Table1[[#This Row],[Monthly]]*(2/3)*0.9)+(MAX(Table1[[#This Row],[MonthsPaid]]-12,0)*Table1[[#This Row],[Monthly]]*(2/3))),2)} -> 180 | M5: {=_xlfn.IFS(Table1[[#This Row],[Age]]>70,"Elderly",Table1[[#This Row],[Age]]>59,"Senior",Table1[[#This Row],[Age]]>49,"Mature Adult",Table1[[#This Row],[Age]]>25,"Adult",Table1[[#This Row],[Age]]>=18,"Young Adult")} -> Adult | N5: Northern Ireland | O5: Email Campaign | P5: Switched Service | Q5: {=_xlfn.IFS(Table1[[#This Row],[TotalRevenue]]<100,"Low",Table1[[#This Row],[TotalRevenue]]<300,"Medium",Table1[[#This Row],[TotalRevenue]]<600,"High",TRUE,"Very High")} -> Medium | R5: {=_xlfn.IFS(Table1[[#This Row],[Age]]>69,"Elderly",Table1[[#This Row],[Age]]>59,"Mature Adult",Table1[[#This Row],[Age]]>25,"Adult",Table1[[#This Row],[Age]]>18,"Young Adult",Table1[[#This Row],[Age]]>=12,"Teenager")} -> Adult | S5: =IF(Table1[[#This Row],[NextBillingDate]]="","Cancelled",IF(Table1[[#This Row],[CancellationDate]]<>"","Cancelled","Active")) -> Cancelled | T5: {=IF(Table1[[#This Row],[ChurnStatus]]="Cancelled",Table1[[#This Row],[TotalRevenue]],Table1[[#This Row],[TotalRevenue]] + Table1[[#This Row],[Discounted]] * _xlfn.IFS(Table1[[#This Row],[SubType]]="Monthly",1,Table1[[#This Row],[SubType]]="6-Month",6-MOD(Table1[[#This Row],[MonthsPaid]],6),Table1[[#This Row],[SubType]]="12-Month",12-MOD(Table1[[#This Row],[MonthsPaid]],12)))} -> 180 | U5: 44923 | W5: 44923 | X5: 0 | Y5: =IF(Table1[[#This Row],[ChurnStatus]]="Cancelled",Table1[[#This Row],[CancellationDate]],TODAY()) -> 44923 | Z5: =IF(AND(Table1[[#This Row],[SubscriptionStart]] <= TODAY(), Table1[[#This Row],[EffectiveEndDate]] >= TODAY()),1,0) -> 0 | AA5: =IF(AND(Table1[[#This Row],[SubscriptionStart]]<=Settings!$A$2,Table1[[#This Row],[EffectiveEndDate]]>=Settings!$A$2),1,0) -> 0 | AB5: =IF(AND(Table1[[#This Row],[SubscriptionStart]]<=Settings!$B$2,Table1[[#This Row],[EffectiveEndDate]]>=Settings!$B$2),1,0) -> 1 | AC5: =IF(AND(Table1[[#This Row],[SubscriptionStart]]<=Settings!$C$2,Table1[[#This Row],[EffectiveEndDate]]>=Settings!$C$2),1,0) -> 0 | AD5: =IF(AND(Table1[[#This Row],[SubscriptionStart]]<=Settings!$D$2,Table1[[#This Row],[EffectiveEndDate]]>=Settings!$D$2),1,0) -> 0 | AE5: =IF(AND(Table1[[#This Row],[SubscriptionStart]]<=Settings!$E$2,Table1[[#This Row],[EffectiveEndDate]]>=Settings!$E$2),1,0) -> 0
A6: CUST0108 | B6: 38 | C6: Female | D6: 44567 | E6: 44747 | F6: =TODAY() - Table1[[#This Row],[SubscriptionStart]] -> 1414 | G6: 6 | H6: 6-Month | I6: Premium | J6: {=_xlfn.IFS(Table1[[#This Row],[Tier]]="Basic",10,Table1[[#This Row],[Tier]]="Standard",18,Table1[[#This Row],[Tier]]="Premium",25)} -> 25 | K6: {=_xlfn.IFS(Table1[[#This Row],[SubType]]="Monthly",IF(Table1[[#This Row],[MonthsPaid]]<=12,Table1[[#This Row],[Monthly]]*0.9,Table1[[#This Row],[Monthly]]),Table1[[#This Row],[SubType]]="6-Month",IF(Table1[[#This Row],[MonthsPaid]]<=12,Table1[[#This Row],[Monthly]]*0.75*0.9,Table1[[#This Row],[Monthly]]*0.75),Table1[[#This Row],[SubType]]="12-Month",IF(Table1[[#This Row],[MonthsPaid]]<=12,Table1[[#This Row],[Monthly]]*(2/3)*0.9,Table1[[#This Row],[Monthly]]*(2/3)))} -> 16.875 | L6: {=ROUND(_xlfn.IFS(Table1[[#This Row],[SubType]]="Monthly",(MAX(MIN(Table1[[#This Row],[MonthsPaid]],12)-1,0)*Table1[[#This Row],[Monthly]]*0.9)+(MAX(Table1[[#This Row],[MonthsPaid]]-12,0)*Table1[[#This Row],[Monthly]]),Table1[[#This Row],[SubType]]="6-Month",(MIN(Table1[[#This Row],[MonthsPaid]],12)*Table1[[#This Row],[Monthly]]*0.75*0.9)+(MAX(Table1[[#This Row],[MonthsPaid]]-12,0)*Table1[[#This Row],[Monthly]]*0.75),Table1[[#This Row],[SubType]]="12-Month",(MIN(Table1[[#This Row],[MonthsPaid]],12)*Table1[[#This Row],[Monthly]]*(2/3)*0.9)+(MAX(Table1[[#This Row],[MonthsPaid]]-12,0)*Table1[[#This Row],[Monthly]]*(2/3))),2)} -> 101.25 | M6: {=_xlfn.IFS(Table1[[#This Row],[Age]]>70,"Elderly",Table1[[#This Row],[Age]]>59,"Senior",Table1[[#This Row],[Age]]>49,"Mature Adult",Table1[[#This Row],[Age]]>25,"Adult",Table1[[#This Row],[Age]]>=18,"Young Adult")} -> Adult | N6: Wales | O6: None | P6: Other | Q6: {=_xlfn.IFS(Table1[[#This Row],[TotalRevenue]]<100,"Low",Table1[[#This Row],[TotalRevenue]]<300,"Medium",Table1[[#This Row],[TotalRevenue]]<600,"High",TRUE,"Very High")} -> Medium | R6: {=_xlfn.IFS(Table1[[#This Row],[Age]]>69,"Elderly",Table1[[#This Row],[Age]]>59,"Mature Adult",Table1[[#This Row],[Age]]>25,"Adult",Table1[[#This Row],[Age]]>18,"Young Adult",Table1[[#This Row],[Age]]>=12,"Teenager")} -> Adult | S6: =IF(Table1[[#This Row],[NextBillingDate]]="","Cancelled",IF(Table1[[#This Row],[CancellationDate]]<>"","Cancelled","Active")) -> Cancelled | T6: {=IF(Table1[[#This Row],[ChurnStatus]]="Cancelled",Table1[[#This Row],[TotalRevenue]],Table1[[#This Row],[TotalRevenue]] + Table1[[#This Row],[Discounted]] * _xlfn.IFS(Table1[[#This Row],[SubType]]="Monthly",1,Table1[[#This Row],[SubType]]="6-Month",6-MOD(Table1[[#This Row],[MonthsPaid]],6),Table1[[#This Row],[SubType]]="12-Month",12-MOD(Table1[[#This Row],[MonthsPaid]],12)))} -> 101.25 | U6: 44747 | W6: 44747 | X6: 0 | Y6: =IF(Table1[[#This Row],[ChurnStatus]]="Cancelled",Table1[[#This Row],[CancellationDate]],TODAY()) -> 44747 | Z6: =IF(AND(Table1[[#This Row],[SubscriptionStart]] <= TODAY(), Table1[[#This Row],[EffectiveEndDate]] >= TODAY()),1,0) -> 0 | AA6: =IF(AND(Table1[[#This Row],[SubscriptionStart]]<=Settings!$A$2,Table1[[#This Row],[EffectiveEndDate]]>=Settings!$A$2),1,0) -> 0 | AB6: =IF(AND(Table1[[#This Row],[SubscriptionStart]]<=Settings!$B$2,Table1[[#This Row],[EffectiveEndDate]]>=Settings!$B$2),1,0) -> 1 | AC6: =IF(AND(Table1[[#This Row],[SubscriptionStart]]<=Settings!$C$2,Table1[[#This Row],[EffectiveEndDate]]>=Settings!$C$2),1,0) -> 0 | AD6: =IF(AND(Table1[[#This Row],[SubscriptionStart]]<=Settings!$D$2,Table1[[#This Row],[EffectiveEndDate]]>=Settings!$D$2),1,0) -> 0 | AE6: =IF(AND(Table1[[#This Row],[SubscriptionStart]]<=Settings!$E$2,Table1[[#This Row],[EffectiveEndDate]]>=Settings!$E$2),1,0) -> 0
A7: CUST0658 | B7: 30 | C7: Female | D7: 44569 | E7: 44599 | F7: =TODAY() - Table1[[#This Row],[SubscriptionStart]] -> 1412 | G7: 1 | H7: Monthly | I7: Standard | J7: {=_xlfn.IFS(Table1[[#This Row],[Tier]]="Basic",10,Table1[[#This Row],[Tier]]="Standard",18,Table1[[#This Row],[Tier]]="Premium",25)} -> 18 | K7: {=_xlfn.IFS(Table1[[#This Row],[SubType]]="Monthly",IF(Table1[[#This Row],[MonthsPaid]]<=12,Table1[[#This Row],[Monthly]]*0.9,Table1[[#This Row],[Monthly]]),Table1[[#This Row],[SubType]]="6-Month",IF(Table1[[#This Row],[MonthsPaid]]<=12,Table1[[#This Row],[Monthly]]*0.75*0.9,Table1[[#This Row],[Monthly]]*0.75),Table1[[#This Row],[SubType]]="12-Month",IF(Table1[[#This Row],[MonthsPaid]]<=12,Table1[[#This Row],[Monthly]]*(2/3)*0.9,Table1[[#This Row],[Monthly]]*(2/3)))} -> 16.2 | L7: {=ROUND(_xlfn.IFS(Table1[[#This Row],[SubType]]="Monthly",(MAX(MIN(Table1[[#This Row],[MonthsPaid]],12)-1,0)*Table1[[#This Row],[Monthly]]*0.9)+(MAX(Table1[[#This Row],[MonthsPaid]]-12,0)*Table1[[#This Row],[Monthly]]),Table1[[#This Row],[SubType]]="6-Month",(MIN(Table1[[#This Row],[MonthsPaid]],12)*Table1[[#This Row],[Monthly]]*0.75*0.9)+(MAX(Table1[[#This Row],[MonthsPaid]]-12,0)*Table1[[#This Row],[Monthly]]*0.75),Table1[[#This Row],[SubType]]="12-Month",(MIN(Table1[[#This Row],[MonthsPaid]],12)*Table1[[#This Row],[Monthly]]*(2/3)*0.9)+(MAX(Table1[[#This Row],[MonthsPaid]]-12,0)*Table1[[#This Row],[Monthly]]*(2/3))),2)} -> 0 | M7: {=_xlfn.IFS(Table1[[#This Row],[Age]]>70,"Elderly",Table1[[#This Row],[Age]]>59,"Senior",Table1[[#This Row],[Age]]>49,"Mature Adult",Table1[[#This Row],[Age]]>25,"Adult",Table1[[#This Row],[Age]]>=18,"Young Adult")} -> Adult | N7: England | O7: Friend | P7: No Longer Needed | Q7: {=_xlfn.IFS(Table1[[#This Row],[TotalRevenue]]<100,"Low",Table1[[#This Row],[TotalRevenue]]<300,"Medium",Table1[[#This Row],[TotalRevenue]]<600,"High",TRUE,"Very High")} -> Low | R7: {=_xlfn.IFS(Table1[[#This Row],[Age]]>69,"Elderly",Table1[[#This Row],[Age]]>59,"Mature Adult",Table1[[#This Row],[Age]]>25,"Adult",Table1[[#This Row],[Age]]>18,"Young Adult",Table1[[#This Row],[Age]]>=12,"Teenager")} -> Adult | S7: =IF(Table1[[#This Row],[NextBillingDate]]="","Cancelled",IF(Table1[[#This Row],[CancellationDate]]<>"","Cancelled","Active")) -> Cancelled | T7: {=IF(Table1[[#This Row],[ChurnStatus]]="Cancelled",Table1[[#This Row],[TotalRevenue]],Table1[[#This Row],[TotalRevenue]] + Table1[[#This Row],[Discounted]] * _xlfn.IFS(Table1[[#This Row],[SubType]]="Monthly",1,Table1[[#This Row],[SubType]]="6-Month",6-MOD(Table1[[#This Row],[MonthsPaid]],6),Table1[[#This Row],[SubType]]="12-Month",12-MOD(Table1[[#This Row],[MonthsPaid]],12)))} -> 0 | U7: 44599 | W7: 44599 | X7: 0 | Y7: =IF(Table1[[#This Row],[ChurnStatus]]="Cancelled",Table1[[#This Row],[CancellationDate]],TODAY()) -> 44599 | Z7: =IF(AND(Table1[[#This Row],[SubscriptionStart]] <= TODAY(), Table1[[#This Row],[EffectiveEndDate]] >= TODAY()),1,0) -> 0 | AA7: =IF(AND(Table1[[#This Row],[SubscriptionStart]]<=Settings!$A$2,Table1[[#This Row],[EffectiveEndDate]]>=Settings!$A$2),1,0) -> 0 | AB7: =IF(AND(Table1[[#This Row],[SubscriptionStart]]<=Settings!$B$2,Table1[[#This Row],[EffectiveEndDate]]>=Settings!$B$2),1,0) -> 0 | AC7: =IF(AND(Table1[[#This Row],[SubscriptionStart]]<=Settings!$C$2,Table1[[#This Row],[EffectiveEndDate]]>=Settings!$C$2),1,0) -> 0 | AD7: =IF(AND(Table1[[#This Row],[SubscriptionStart]]<=Settings!$D$2,Table1[[#This Row],[EffectiveEndDate]]>=Settings!$D$2),1,0) -> 0 | AE7: =IF(AND(Table1[[#This Row],[SubscriptionStart]]<=Settings!$E$2,Table1[[#This Row],[EffectiveEndDate]]>=Settings!$E$2),1,0) -> 0
A8: CUST0269 | B8: 43 | C8: Male | D8: 44569 | F8: =TODAY() - Table1[[#This Row],[SubscriptionStart]] -> 1412 | G8: 48 | H8: 6-Month | I8: Basic | J8: {=_xlfn.IFS(Table1[[#This Row],[Tier]]="Basic",10,Table1[[#This Row],[Tier]]="Standard",18,Table1[[#This Row],[Tier]]="Premium",25)} -> 10 | K8: {=_xlfn.IFS(Table1[[#This Row],[SubType]]="Monthly",IF(Table1[[#This Row],[MonthsPaid]]<=12,Table1[[#This Row],[Monthly]]*0.9,Table1[[#This Row],[Monthly]]),Table1[[#This Row],[SubType]]="6-Month",IF(Table1[[#This Row],[MonthsPaid]]<=12,Table1[[#This Row],[Monthly]]*0.75*0.9,Table1[[#This Row],[Monthly]]*0.75),Table1[[#This Row],[SubType]]="12-Month",IF(Table1[[#This Row],[MonthsPaid]]<=12,Table1[[#This Row],[Monthly]]*(2/3)*0.9,Table1[[#This Row],[Monthly]]*(2/3)))} -> 7.5 | L8: {=ROUND(_xlfn.IFS(Table1[[#This Row],[SubType]]="Monthly",(MAX(MIN(Table1[[#This Row],[MonthsPaid]],12)-1,0)*Table1[[#This Row],[Monthly]]*0.9)+(MAX(Table1[[#This Row],[MonthsPaid]]-12,0)*Table1[[#This Row],[Monthly]]),Table1[[#This Row],[SubType]]="6-Month",(MIN(Table1[[#This Row],[MonthsPaid]],12)*Table1[[#This Row],[Monthly]]*0.75*0.9)+(MAX(Table1[[#This Row],[MonthsPaid]]-12,0)*Table1[[#This Row],[Monthly]]*0.75),Table1[[#This Row],[SubType]]="12-Month",(MIN(Table1[[#This Row],[MonthsPaid]],12)*Table1[[#This Row],[Monthly]]*(2/3)*0.9)+(MAX(Table1[[#This Row],[MonthsPaid]]-12,0)*Table1[[#This Row],[Monthly]]*(2/3))),2)} -> 351 | M8: {=_xlfn.IFS(Table1[[#This Row],[Age]]>70,"Elderly",Table1[[#This Row],[Age]]>59,"Senior",Table1[[#This Row],[Age]]>49,"Mature Adult",Table1[[#This Row],[Age]]>25,"Adult",Table1[[#This Row],[Age]]>=18,"Young Adult")} -> Adult | N8: Northern Ireland | O8: Email Campaign | Q8: {=_xlfn.IFS(Table1[[#This Row],[TotalRevenue]]<100,"Low",Table1[[#This Row],[TotalRevenue]]<300,"Medium",Table1[[#This Row],[TotalRevenue]]<600,"High",TRUE,"Very High")} -> High | R8: {=_xlfn.IFS(Table1[[#This Row],[Age]]>69,"Elderly",Table1[[#This Row],[Age]]>59,"Mature Adult",Table1[[#This Row],[Age]]>25,"Adult",Table1[[#This Row],[Age]]>18,"Young Adult",Table1[[#This Row],[Age]]>=12,"Teenager")} -> Adult | S8: =IF(Table1[[#This Row],[NextBillingDate]]="","Cancelled",IF(Table1[[#This Row],[CancellationDate]]<>"","Cancelled","Active")) -> Active | T8: {=IF(Table1[[#This Row],[ChurnStatus]]="Cancelled",Table1[[#This Row],[TotalRevenue]],Table1[[#This Row],[TotalRevenue]] + Table1[[#This Row],[Discounted]] * _xlfn.IFS(Table1[[#This Row],[SubType]]="Monthly",1,Table1[[#This Row],[SubType]]="6-Month",6-MOD(Table1[[#This Row],[MonthsPaid]],6),Table1[[#This Row],[SubType]]="12-Month",12-MOD(Table1[[#This Row],[MonthsPaid]],12)))} -> 396 | V8: 46009 | W8: 46009 | X8: 7 | Y8: =IF(Table1[[#This Row],[ChurnStatus]]="Cancelled",Table1[[#This Row],[CancellationDate]],TODAY()) -> 45981 | Z8: =IF(AND(Table1[[#This Row],[SubscriptionStart]] <= TODAY(), Table1[[#This Row],[EffectiveEndDate]] >= TODAY()),1,0) -> 1 | AA8: =IF(AND(Table1[[#This Row],[SubscriptionStart]]<=Settings!$A$2,Table1[[#This Row],[EffectiveEndDate]]>=Settings!$A$2),1,0) -> 0 | AB8: =IF(AND(Table1[[#This Row],[SubscriptionStart]]<=Settings!$B$2,Table1[[#This Row],[EffectiveEndDate]]>=Settings!$B$2),1,0) -> 1 | AC8: =IF(AND(Table1[[#This Row],[SubscriptionStart]]<=Settings!$C$2,Table1[[#This Row],[EffectiveEndDate]]>=Settings!$C$2),1,0) -> 1 | AD8: =IF(AND(Table1[[#This Row],[SubscriptionStart]]<=Settings!$D$2,Table1[[#This Row],[EffectiveEndDate]]>=Settings!$D$2),1,0) -> 1 | AE8: =IF(AND(Table1[[#This Row],[SubscriptionStart]]<=Settings!$E$2,Table1[[#This Row],[EffectiveEndDate]]>=Settings!$E$2),1,0) -> 1
A9: CUST0522 | B9: 30 | C9: Male | D9: 44570 | E9: 44600 | F9: =TODAY() - Table1[[#This Row],[SubscriptionStart]] -> 1411 | G9: 1 | H9: Monthly | I9: Basic | J9: {=_xlfn.IFS(Table1[[#This Row],[Tier]]="Basic",10,Table1[[#This Row],[Tier]]="Standard",18,Table1[[#This Row],[Tier]]="Premium",25)} -> 10 | K9: {=_xlfn.IFS(Table1[[#This Row],[SubType]]="Monthly",IF(Table1[[#This Row],[MonthsPaid]]<=12,Table1[[#This Row],[Monthly]]*0.9,Table1[[#This Row],[Monthly]]),Table1[[#This Row],[SubType]]="6-Month",IF(Table1[[#This Row],[MonthsPaid]]<=12,Table1[[#This Row],[Monthly]]*0.75*0.9,Table1[[#This Row],[Monthly]]*0.75),Table1[[#This Row],[SubType]]="12-Month",IF(Table1[[#This Row],[MonthsPaid]]<=12,Table1[[#This Row],[Monthly]]*(2/3)*0.9,Table1[[#This Row],[Monthly]]*(2/3)))} -> 9 | L9: {=ROUND(_xlfn.IFS(Table1[[#This Row],[SubType]]="Monthly",(MAX(MIN(Table1[[#This Row],[MonthsPaid]],12)-1,0)*Table1[[#This Row],[Monthly]]*0.9)+(MAX(Table1[[#This Row],[MonthsPaid]]-12,0)*Table1[[#This Row],[Monthly]]),Table1[[#This Row],[SubType]]="6-Month",(MIN(Table1[[#This Row],[MonthsPaid]],12)*Table1[[#This Row],[Monthly]]*0.75*0.9)+(MAX(Table1[[#This Row],[MonthsPaid]]-12,0)*Table1[[#This Row],[Monthly]]*0.75),Table1[[#This Row],[SubType]]="12-Month",(MIN(Table1[[#This Row],[MonthsPaid]],12)*Table1[[#This Row],[Monthly]]*(2/3)*0.9)+(MAX(Table1[[#This Row],[MonthsPaid]]-12,0)*Table1[[#This Row],[Monthly]]*(2/3))),2)} -> 0 | M9: {=_xlfn.IFS(Table1[[#This Row],[Age]]>70,"Elderly",Table1[[#This Row],[Age]]>59,"Senior",Table1[[#This Row],[Age]]>49,"Mature Adult",Table1[[#This Row],[Age]]>25,"Adult",Table1[[#This Row],[Age]]>=18,"Young Adult")} -> Adult | N9: Scotland | O9: Social Media | P9: Other | Q9: {=_xlfn.IFS(Table1[[#This Row],[TotalRevenue]]<100,"Low",Table1[[#This Row],[TotalRevenue]]<300,"Medium",Table1[[#This Row],[TotalRevenue]]<600,"High",TRUE,"Very High")} -> Low | R9: {=_xlfn.IFS(Table1[[#This Row],[Age]]>69,"Elderly",Table1[[#This Row],[Age]]>59,"Mature Adult",Table1[[#This Row],[Age]]>25,"Adult",Table1[[#This Row],[Age]]>18,"Young Adult",Table1[[#This Row],[Age]]>=12,"Teenager")} -> Adult | S9: =IF(Table1[[#This Row],[NextBillingDate]]="","Cancelled",IF(Table1[[#This Row],[CancellationDate]]<>"","Cancelled","Active")) -> Cancelled | T9: {=IF(Table1[[#This Row],[ChurnStatus]]="Cancelled",Table1[[#This Row],[TotalRevenue]],Table1[[#This Row],[TotalRevenue]] + Table1[[#This Row],[Discounted]] * _xlfn.IFS(Table1[[#This Row],[SubType]]="Monthly",1,Table1[[#This Row],[SubType]]="6-Month",6-MOD(Table1[[#This Row],[MonthsPaid]],6),Table1[[#This Row],[SubType]]="12-Month",12-MOD(Table1[[#This Row],[MonthsPaid]],12)))} -> 0 | U9: 44600 | W9: 44600 | X9: 0 | Y9: =IF(Table1[[#This Row],[ChurnStatus]]="Cancelled",Table1[[#This Row],[CancellationDate]],TODAY()) -> 44600 | Z9: =IF(AND(Table1[[#This Row],[SubscriptionStart]] <= TODAY(), Table1[[#This Row],[EffectiveEndDate]] >= TODAY()),1,0) -> 0 | AA9: =IF(AND(Table1[[#This Row],[SubscriptionStart]]<=Settings!$A$2,Table1[[#This Row],[EffectiveEndDate]]>=Settings!$A$2),1,0) -> 0 | AB9: =IF(AND(Table1[[#This Row],[SubscriptionStart]]<=Settings!$B$2,Table1[[#This Row],[EffectiveEndDate]]>=Settings!$B$2),1,0) -> 0 | AC9: =IF(AND(Table1[[#This Row],[SubscriptionStart]]<=Settings!$C$2,Table1[[#This Row],[EffectiveEndDate]]>=Settings!$C$2),1,0) -> 0 | AD9: =IF(AND(Table1[[#This Row],[SubscriptionStart]]<=Settings!$D$2,Table1[[#This Row],[EffectiveEndDate]]>=Settings!$D$2),1,0) -> 0 | AE9: =IF(AND(Table1[[#This Row],[SubscriptionStart]]<=Settings!$E$2,Table1[[#This Row],[EffectiveEndDate]]>=Settings!$E$2),1,0) -> 0
A10: CUST0285 | B10: 46 | C10: Male | D10: 44570 | F10: =TODAY() - Table1[[#This Row],[SubscriptionStart]] -> 1411 | G10: 48 | H10: 6-Month | I10: Standard | J10: {=_xlfn.IFS(Table1[[#This Row],[Tier]]="Basic",10,Table1[[#This Row],[Tier]]="Standard",18,Table1[[#This Row],[Tier]]="Premium",25)} -> 18 | K10: {=_xlfn.IFS(Table1[[#This Row],[SubType]]="Monthly",IF(Table1[[#This Row],[MonthsPaid]]<=12,Table1[[#This Row],[Monthly]]*0.9,Table1[[#This Row],[Monthly]]),Table1[[#This Row],[SubType]]="6-Month",IF(Table1[[#This Row],[MonthsPaid]]<=12,Table1[[#This Row],[Monthly]]*0.75*0.9,Table1[[#This Row],[Monthly]]*0.75),Table1[[#This Row],[SubType]]="12-Month",IF(Table1[[#This Row],[MonthsPaid]]<=12,Table1[[#This Row],[Monthly]]*(2/3)*0.9,Table1[[#This Row],[Monthly]]*(2/3)))} -> 13.5 | L10: {=ROUND(_xlfn.IFS(Table1[[#This Row],[SubType]]="Monthly",(MAX(MIN(Table1[[#This Row],[MonthsPaid]],12)-1,0)*Table1[[#This Row],[Monthly]]*0.9)+(MAX(Table1[[#This Row],[MonthsPaid]]-12,0)*Table1[[#This Row],[Monthly]]),Table1[[#This Row],[SubType]]="6-Month",(MIN(Table1[[#This Row],[MonthsPaid]],12)*Table1[[#This Row],[Monthly]]*0.75*0.9)+(MAX(Table1[[#This Row],[MonthsPaid]]-12,0)*Table1[[#This Row],[Monthly]]*0.75),Table1[[#This Row],[SubType]]="12-Month",(MIN(Table1[[#This Row],[MonthsPaid]],12)*Table1[[#This Row],[Monthly]]*(2/3)*0.9)+(MAX(Table1[[#This Row],[MonthsPaid]]-12,0)*Table1[[#This Row],[Monthly]]*(2/3))),2)} -> 631.8 | M10: {=_xlfn.IFS(Table1[[#This Row],[Age]]>70,"Elderly",Table1[[#This Row],[Age]]>59,"Senior",Table1[[#This Row],[Age]]>49,"Mature Adult",Table1[[#This Row],[Age]]>25,"Adult",Table1[[#This Row],[Age]]>=18,"Young Adult")} -> Adult | N10: Scotland | O10: Social Media | Q10: {=_xlfn.IFS(Table1[[#This Row],[TotalRevenue]]<100,"Low",Table1[[#This Row],[TotalRevenue]]<300,"Medium",Table1[[#This Row],[TotalRevenue]]<600,"High",TRUE,"Very High")} -> Very High | R10: {=_xlfn.IFS(Table1[[#This Row],[Age]]>69,"Elderly",Table1[[#This Row],[Age]]>59,"Mature Adult",Table1[[#This Row],[Age]]>25,"Adult",Table1[[#This Row],[Age]]>18,"Young Adult",Table1[[#This Row],[Age]]>=12,"Teenager")} -> Adult | S10: =IF(Table1[[#This Row],[NextBillingDate]]="","Cancelled",IF(Table1[[#This Row],[CancellationDate]]<>"","Cancelled","Active")) -> Active | T10: {=IF(Table1[[#This Row],[ChurnStatus]]="Cancelled",Table1[[#This Row],[TotalRevenue]],Table1[[#This Row],[TotalRevenue]] + Table1[[#This Row],[Discounted]] * _xlfn.IFS(Table1[[#This Row],[SubType]]="Monthly",1,Table1[[#This Row],[SubType]]="6-Month",6-MOD(Table1[[#This Row],[MonthsPaid]],6),Table1[[#This Row],[SubType]]="12-Month",12-MOD(Table1[[#This Row],[MonthsPaid]],12)))} -> 712.8 | V10: 46010 | W10: 46010 | X10: 7 | Y10: =IF(Table1[[#This Row],[ChurnStatus]]="Cancelled",Table1[[#This Row],[CancellationDate]],TODAY()) -> 45981 | Z10: =IF(AND(Table1[[#This Row],[SubscriptionStart]] <= TODAY(), Table1[[#This Row],[EffectiveEndDate]] >= TODAY()),1,0) -> 1 | AA10: =IF(AND(Table1[[#This Row],[SubscriptionStart]]<=Settings!$A$2,Table1[[#This Row],[EffectiveEndDate]]>=Settings!$A$2),1,0) -> 0 | AB10: =IF(AND(Table1[[#This Row],[SubscriptionStart]]<=Settings!$B$2,Table1[[#This Row],[EffectiveEndDate]]>=Settings!$B$2),1,0) -> 1 | AC10: =IF(AND(Table1[[#This Row],[SubscriptionStart]]<=Settings!$C$2,Table1[[#This Row],[EffectiveEndDate]]>=Settings!$C$2),1,0) -> 1 | AD10: =IF(AND(Table1[[#This Row],[SubscriptionStart]]<=Settings!$D$2,Table1[[#This Row],[EffectiveEndDate]]>=Settings!$D$2),1,0) -> 1 | AE10: =IF(AND(Table1[[#This Row],[SubscriptionStart]]<=Settings!$E$2,Table1[[#This Row],[EffectiveEndDate]]>=Settings!$E$2),1,0) -> 1
A11: CUST0695 | B11: 30 | C11: Female | D11: 44573 | E11: 44933 | F11: =TODAY() - Table1[[#This Row],[SubscriptionStart]] -> 1408 | G11: 12 | H11: 12-Month | I11: Basic | J11: {=_xlfn.IFS(Table1[[#This Row],[Tier]]="Basic",10,Table1[[#This Row],[Tier]]="Standard",18,Table1[[#This Row],[Tier]]="Premium",25)} -> 10 | K11: {=_xlfn.IFS(Table1[[#This Row],[SubType]]="Monthly",IF(Table1[[#This Row],[MonthsPaid]]<=12,Table1[[#This Row],[Monthly]]*0.9,Table1[[#This Row],[Monthly]]),Table1[[#This Row],[SubType]]="6-Month",IF(Table1[[#This Row],[MonthsPaid]]<=12,Table1[[#This Row],[Monthly]]*0.75*0.9,Table1[[#This Row],[Monthly]]*0.75),Table1[[#This Row],[SubType]]="12-Month",IF(Table1[[#This Row],[MonthsPaid]]<=12,Table1[[#This Row],[Monthly]]*(2/3)*0.9,Table1[[#This Row],[Monthly]]*(2/3)))} -> 6 | L11: {=ROUND(_xlfn.IFS(Table1[[#This Row],[SubType]]="Monthly",(MAX(MIN(Table1[[#This Row],[MonthsPaid]],12)-1,0)*Table1[[#This Row],[Monthly]]*0.9)+(MAX(Table1[[#This Row],[MonthsPaid]]-12,0)*Table1[[#This Row],[Monthly]]),Table1[[#This Row],[SubType]]="6-Month",(MIN(Table1[[#This Row],[MonthsPaid]],12)*Table1[[#This Row],[Monthly]]*0.75*0.9)+(MAX(Table1[[#This Row],[MonthsPaid]]-12,0)*Table1[[#This Row],[Monthly]]*0.75),Table1[[#This Row],[SubType]]="12-Month",(MIN(Table1[[#This Row],[MonthsPaid]],12)*Table1[[#This Row],[Monthly]]*(2/3)*0.9)+(MAX(Table1[[#This Row],[MonthsPaid]]-12,0)*Table1[[#This Row],[Monthly]]*(2/3))),2)} -> 72 | M11: {=_xlfn.IFS(Table1[[#This Row],[Age]]>70,"Elderly",Table1[[#This Row],[Age]]>59,"Senior",Table1[[#This Row],[Age]]>49,"Mature Adult",Table1[[#This Row],[Age]]>25,"Adult",Table1[[#This Row],[Age]]>=18,"Young Adult")} -> Adult | N11: Wales | O11: Friend | P11: Too Expensive | Q11: {=_xlfn.IFS(Table1[[#This Row],[TotalRevenue]]<100,"Low",Table1[[#This Row],[TotalRevenue]]<300,"Medium",Table1[[#This Row],[TotalRevenue]]<600,"High",TRUE,"Very High")} -> Low | R11: {=_xlfn.IFS(Table1[[#This Row],[Age]]>69,"Elderly",Table1[[#This Row],[Age]]>59,"Mature Adult",Table1[[#This Row],[Age]]>25,"Adult",Table1[[#This Row],[Age]]>18,"Young Adult",Table1[[#This Row],[Age]]>=12,"Teenager")} -> Adult | S11: =IF(Table1[[#This Row],[NextBillingDate]]="","Cancelled",IF(Table1[[#This Row],[CancellationDate]]<>"","Cancelled","Active")) -> Cancelled | T11: {=IF(Table1[[#This Row],[ChurnStatus]]="Cancelled",Table1[[#This Row],[TotalRevenue]],Table1[[#This Row],[TotalRevenue]] + Table1[[#This Row],[Discounted]] * _xlfn.IFS(Table1[[#This Row],[SubType]]="Monthly",1,Table1[[#This Row],[SubType]]="6-Month",6-MOD(Table1[[#This Row],[MonthsPaid]],6),Table1[[#This Row],[SubType]]="12-Month",12-MOD(Table1[[#This Row],[MonthsPaid]],12)))} -> 72 | U11: 44933 | W11: 44933 | X11: 0 | Y11: =IF(Table1[[#This Row],[ChurnStatus]]="Cancelled",Table1[[#This Row],[CancellationDate]],TODAY()) -> 44933 | Z11: =IF(AND(Table1[[#This Row],[SubscriptionStart]] <= TODAY(), Table1[[#This Row],[EffectiveEndDate]] >= TODAY()),1,0) -> 0 | AA11: =IF(AND(Table1[[#This Row],[SubscriptionStart]]<=Settings!$A$2,Table1[[#This Row],[EffectiveEndDate]]>=Settings!$A$2),1,0) -> 0 | AB11: =IF(AND(Table1[[#This Row],[SubscriptionStart]]<=Settings!$B$2,Table1[[#This Row],[EffectiveEndDate]]>=Settings!$B$2),1,0) -> 1 | AC11: =IF(AND(Table1[[#This Row],[SubscriptionStart]]<=Settings!$C$2,Table1[[#This Row],[EffectiveEndDate]]>=Settings!$C$2),1,0) -> 1 | AD11: =IF(AND(Table1[[#This Row],[SubscriptionStart]]<=Settings!$D$2,Table1[[#This Row],[EffectiveEndDate]]>=Settings!$D$2),1,0) -> 0 | AE11: =IF(AND(Table1[[#This Row],[SubscriptionStart]]<=Settings!$E$2,Table1[[#This Row],[EffectiveEndDate]]>=Settings!$E$2),1,0) -> 0
A12: CUST0223 | B12: 45 | C12: Female | D12: 44576 | E12: 44606 | F12: =TODAY() - Table1[[#This Row],[SubscriptionStart]] -> 1405 | G12: 1 | H12: Monthly | I12: Standard | J12: {=_xlfn.IFS(Table1[[#This Row],[Tier]]="Basic",10,Table1[[#This Row],[Tier]]="Standard",18,Table1[[#This Row],[Tier]]="Premium",25)} -> 18 | K12: {=_xlfn.IFS(Table1[[#This Row],[SubType]]="Monthly",IF(Table1[[#This Row],[MonthsPaid]]<=12,Table1[[#This Row],[Monthly]]*0.9,Table1[[#This Row],[Monthly]]),Table1[[#This Row],[SubType]]="6-Month",IF(Table1[[#This Row],[MonthsPaid]]<=12,Table1[[#This Row],[Monthly]]*0.75*0.9,Table1[[#This Row],[Monthly]]*0.75),Table1[[#This Row],[SubType]]="12-Month",IF(Table1[[#This Row],[MonthsPaid]]<=12,Table1[[#This Row],[Monthly]]*(2/3)*0.9,Table1[[#This Row],[Monthly]]*(2/3)))} -> 16.2 | L12: {=ROUND(_xlfn.IFS(Table1[[#This Row],[SubType]]="Monthly",(MAX(MIN(Table1[[#This Row],[MonthsPaid]],12)-1,0)*Table1[[#This Row],[Monthly]]*0.9)+(MAX(Table1[[#This Row],[MonthsPaid]]-12,0)*Table1[[#This Row],[Monthly]]),Table1[[#This Row],[SubType]]="6-Month",(MIN(Table1[[#This Row],[MonthsPaid]],12)*Table1[[#This Row],[Monthly]]*0.75*0.9)+(MAX(Table1[[#This Row],[MonthsPaid]]-12,0)*Table1[[#This Row],[Monthly]]*0.75),Table1[[#This Row],[SubType]]="12-Month",(MIN(Table1[[#This Row],[MonthsPaid]],12)*Table1[[#This Row],[Monthly]]*(2/3)*0.9)+(MAX(Table1[[#This Row],[MonthsPaid]]-12,0)*Table1[[#This Row],[Monthly]]*(2/3))),2)} -> 0 | M12: {=_xlfn.IFS(Table1[[#This Row],[Age]]>70,"Elderly",Table1[[#This Row],[Age]]>59,"Senior",Table1[[#This Row],[Age]]>49,"Mature Adult",Table1[[#This Row],[Age]]>25,"Adult",Table1[[#This Row],[Age]]>=18,"Young Adult")} -> Adult | N12: Wales | O12: None | P12: No Longer Needed | Q12: {=_xlfn.IFS(Table1[[#This Row],[TotalRevenue]]<100,"Low",Table1[[#This Row],[TotalRevenue]]<300,"Medium",Table1[[#This Row],[TotalRevenue]]<600,"High",TRUE,"Very High")} -> Low | R12: {=_xlfn.IFS(Table1[[#This Row],[Age]]>69,"Elderly",Table1[[#This Row],[Age]]>59,"Mature Adult",Table1[[#This Row],[Age]]>25,"Adult",Table1[[#This Row],[Age]]>18,"Young Adult",Table1[[#This Row],[Age]]>=12,"Teenager")} -> Adult | S12: =IF(Table1[[#This Row],[NextBillingDate]]="","Cancelled",IF(Table1[[#This Row],[CancellationDate]]<>"","Cancelled","Active")) -> Cancelled | T12: {=IF(Table1[[#This Row],[ChurnStatus]]="Cancelled",Table1[[#This Row],[TotalRevenue]],Table1[[#This Row],[TotalRevenue]] + Table1[[#This Row],[Discounted]] * _xlfn.IFS(Table1[[#This Row],[SubType]]="Monthly",1,Table1[[#This Row],[SubType]]="6-Month",6-MOD(Table1[[#This Row],[MonthsPaid]],6),Table1[[#This Row],[SubType]]="12-Month",12-MOD(Table1[[#This Row],[MonthsPaid]],12)))} -> 0 | U12: 44606 | W12: 44606 | X12: 0 | Y12: =IF(Table1[[#This Row],[ChurnStatus]]="Cancelled",Table1[[#This Row],[CancellationDate]],TODAY()) -> 44606 | Z12: =IF(AND(Table1[[#This Row],[SubscriptionStart]] <= TODAY(), Table1[[#This Row],[EffectiveEndDate]] >= TODAY()),1,0) -> 0 | AA12: =IF(AND(Table1[[#This Row],[SubscriptionStart]]<=Settings!$A$2,Table1[[#This Row],[EffectiveEndDate]]>=Settings!$A$2),1,0) -> 0 | AB12: =IF(AND(Table1[[#This Row],[SubscriptionStart]]<=Settings!$B$2,Table1[[#This Row],[EffectiveEndDate]]>=Settings!$B$2),1,0) -> 0 | AC12: =IF(AND(Table1[[#This Row],[SubscriptionStart]]<=Settings!$C$2,Table1[[#This Row],[EffectiveEndDate]]>=Settings!$C$2),1,0) -> 0 | AD12: =IF(AND(Table1[[#This Row],[SubscriptionStart]]<=Settings!$D$2,Table1[[#This Row],[EffectiveEndDate]]>=Settings!$D$2),1,0) -> 0 | AE12: =IF(AND(Table1[[#This Row],[SubscriptionStart]]<=Settings!$E$2,Table1[[#This Row],[EffectiveEndDate]]>=Settings!$E$2),1,0) -> 0
A13: CUST0092 | B13: 19 | C13: Male | D13: 44577 | E13: 44607 | F13: =TODAY() - Table1[[#This Row],[SubscriptionStart]] -> 1404 | G13: 1 | H13: Monthly | I13: Basic | J13: {=_xlfn.IFS(Table1[[#This Row],[Tier]]="Basic",10,Table1[[#This Row],[Tier]]="Standard",18,Table1[[#This Row],[Tier]]="Premium",25)} -> 10 | K13: {=_xlfn.IFS(Table1[[#This Row],[SubType]]="Monthly",IF(Table1[[#This Row],[MonthsPaid]]<=12,Table1[[#This Row],[Monthly]]*0.9,Table1[[#This Row],[Monthly]]),Table1[[#This Row],[SubType]]="6-Month",IF(Table1[[#This Row],[MonthsPaid]]<=12,Table1[[#This Row],[Monthly]]*0.75*0.9,Table1[[#This Row],[Monthly]]*0.75),Table1[[#This Row],[SubType]]="12-Month",IF(Table1[[#This Row],[MonthsPaid]]<=12,Table1[[#This Row],[Monthly]]*(2/3)*0.9,Table1[[#This Row],[Monthly]]*(2/3)))} -> 9 | L13: {=ROUND(_xlfn.IFS(Table1[[#This Row],[SubType]]="Monthly",(MAX(MIN(Table1[[#This Row],[MonthsPaid]],12)-1,0)*Table1[[#This Row],[Monthly]]*0.9)+(MAX(Table1[[#This Row],[MonthsPaid]]-12,0)*Table1[[#This Row],[Monthly]]),Table1[[#This Row],[SubType]]="6-Month",(MIN(Table1[[#This Row],[MonthsPaid]],12)*Table1[[#This Row],[Monthly]]*0.75*0.9)+(MAX(Table1[[#This Row],[MonthsPaid]]-12,0)*Table1[[#This Row],[Monthly]]*0.75),Table1[[#This Row],[SubType]]="12-Month",(MIN(Table1[[#This Row],[MonthsPaid]],12)*Table1[[#This Row],[Monthly]]*(2/3)*0.9)+(MAX(Table1[[#This Row],[MonthsPaid]]-12,0)*Table1[[#This Row],[Monthly]]*(2/3))),2)} -> 0 | M13: {=_xlfn.IFS(Table1[[#This Row],[Age]]>70,"Elderly",Table1[[#This Row],[Age]]>59,"Senior",Table1[[#This Row],[Age]]>49,"Mature Adult",Table1[[#This Row],[Age]]>25,"Adult",Table1[[#This Row],[Age]]>=18,"Young Adult")} -> Young Adult | N13: Scotland | O13: Social Media | P13: Poor Experience | Q13: {=_xlfn.IFS(Table1[[#This Row],[TotalRevenue]]<100,"Low",Table1[[#This Row],[TotalRevenue]]<300,"Medium",Table1[[#This Row],[TotalRevenue]]<600,"High",TRUE,"Very High")} -> Low | R13: {=_xlfn.IFS(Table1[[#This Row],[Age]]>69,"Elderly",Table1[[#This Row],[Age]]>59,"Mature Adult",Table1[[#This Row],[Age]]>25,"Adult",Table1[[#This Row],[Age]]>18,"Young Adult",Table1[[#This Row],[Age]]>=12,"Teenager")} -> Young Adult | S13: =IF(Table1[[#This Row],[NextBillingDate]]="","Cancelled",IF(Table1[[#This Row],[CancellationDate]]<>"","Cancelled","Active")) -> Cancelled | T13: {=IF(Table1[[#This Row],[ChurnStatus]]="Cancelled",Table1[[#This Row],[TotalRevenue]],Table1[[#This Row],[TotalRevenue]] + Table1[[#This Row],[Discounted]] * _xlfn.IFS(Table1[[#This Row],[SubType]]="Monthly",1,Table1[[#This Row],[SubType]]="6-Month",6-MOD(Table1[[#This Row],[MonthsPaid]],6),Table1[[#This Row],[SubType]]="12-Month",12-MOD(Table1[[#This Row],[MonthsPaid]],12)))} -> 0 | U13: 44607 | W13: 44607 | X13: 0 | Y13: =IF(Table1[[#This Row],[ChurnStatus]]="Cancelled",Table1[[#This Row],[CancellationDate]],TODAY()) -> 44607 | Z13: =IF(AND(Table1[[#This Row],[SubscriptionStart]] <= TODAY(), Table1[[#This Row],[EffectiveEndDate]] >= TODAY()),1,0) -> 0 | AA13: =IF(AND(Table1[[#This Row],[SubscriptionStart]]<=Settings!$A$2,Table1[[#This Row],[EffectiveEndDate]]>=Settings!$A$2),1,0) -> 0 | AB13: =IF(AND(Table1[[#This Row],[SubscriptionStart]]<=Settings!$B$2,Table1[[#This Row],[EffectiveEndDate]]>=Settings!$B$2),1,0) -> 0 | AC13: =IF(AND(Table1[[#This Row],[SubscriptionStart]]<=Settings!$C$2,Table1[[#This Row],[EffectiveEndDate]]>=Settings!$C$2),1,0) -> 0 | AD13: =IF(AND(Table1[[#This Row],[SubscriptionStart]]<=Settings!$D$2,Table1[[#This Row],[EffectiveEndDate]]>=Settings!$D$2),1,0) -> 0 | AE13: =IF(AND(Table1[[#This Row],[SubscriptionStart]]<=Settings!$E$2,Table1[[#This Row],[EffectiveEndDate]]>=Settings!$E$2),1,0) -> 0
A14: CUST0349 | B14: 64 | C14: Male | D14: 44577 | E14: 44937 | F14: =TODAY() - Table1[[#This Row],[SubscriptionStart]] -> 1404 | G14: 12 | H14: 12-Month | I14: Standard | J14: {=_xlfn.IFS(Table1[[#This Row],[Tier]]="Basic",10,Table1[[#This Row],[Tier]]="Standard",18,Table1[[#This Row],[Tier]]="Premium",25)} -> 18 | K14: {=_xlfn.IFS(Table1[[#This Row],[SubType]]="Monthly",IF(Table1[[#This Row],[MonthsPaid]]<=12,Table1[[#This Row],[Monthly]]*0.9,Table1[[#This Row],[Monthly]]),Table1[[#This Row],[SubType]]="6-Month",IF(Table1[[#This Row],[MonthsPaid]]<=12,Table1[[#This Row],[Monthly]]*0.75*0.9,Table1[[#This Row],[Monthly]]*0.75),Table1[[#This Row],[SubType]]="12-Month",IF(Table1[[#This Row],[MonthsPaid]]<=12,Table1[[#This Row],[Monthly]]*(2/3)*0.9,Table1[[#This Row],[Monthly]]*(2/3)))} -> 10.8 | L14: {=ROUND(_xlfn.IFS(Table1[[#This Row],[SubType]]="Monthly",(MAX(MIN(Table1[[#This Row],[MonthsPaid]],12)-1,0)*Table1[[#This Row],[Monthly]]*0.9)+(MAX(Table1[[#This Row],[MonthsPaid]]-12,0)*Table1[[#This Row],[Monthly]]),Table1[[#This Row],[SubType]]="6-Month",(MIN(Table1[[#This Row],[MonthsPaid]],12)*Table1[[#This Row],[Monthly]]*0.75*0.9)+(MAX(Table1[[#This Row],[MonthsPaid]]-12,0)*Table1[[#This Row],[Monthly]]*0.75),Table1[[#This Row],[SubType]]="12-Month",(MIN(Table1[[#This Row],[MonthsPaid]],12)*Table1[[#This Row],[Monthly]]*(2/3)*0.9)+(MAX(Table1[[#This Row],[MonthsPaid]]-12,0)*Table1[[#This Row],[Monthly]]*(2/3))),2)} -> 129.6 | M14: {=_xlfn.IFS(Table1[[#This Row],[Age]]>70,"Elderly",Table1[[#This Row],[Age]]>59,"Senior",Table1[[#This Row],[Age]]>49,"Mature Adult",Table1[[#This Row],[Age]]>25,"Adult",Table1[[#This Row],[Age]]>=18,"Young Adult")} -> Senior | N14: England | O14: Email Campaign | P14: Switched Service | Q14: {=_xlfn.IFS(Table1[[#This Row],[TotalRevenue]]<100,"Low",Table1[[#This Row],[TotalRevenue]]<300,"Medium",Table1[[#This Row],[TotalRevenue]]<600,"High",TRUE,"Very High")} -> Medium | R14: {=_xlfn.IFS(Table1[[#This Row],[Age]]>69,"Elderly",Table1[[#This Row],[Age]]>59,"Mature Adult",Table1[[#This Row],[Age]]>25,"Adult",Table1[[#This Row],[Age]]>18,"Young Adult",Table1[[#This Row],[Age]]>=12,"Teenager")} -> Mature Adult | S14: =IF(Table1[[#This Row],[NextBillingDate]]="","Cancelled",IF(Table1[[#This Row],[CancellationDate]]<>"","Cancelled","Active")) -> Cancelled | T14: {=IF(Table1[[#This Row],[ChurnStatus]]="Cancelled",Table1[[#This Row],[TotalRevenue]],Table1[[#This Row],[TotalRevenue]] + Table1[[#This Row],[Discounted]] * _xlfn.IFS(Table1[[#This Row],[SubType]]="Monthly",1,Table1[[#This Row],[SubType]]="6-Month",6-MOD(Table1[[#This Row],[MonthsPaid]],6),Table1[[#This Row],[SubType]]="12-Month",12-MOD(Table1[[#This Row],[MonthsPaid]],12)))} -> 129.6 | U14: 44937 | W14: 44937 | X14: 0 | Y14: =IF(Table1[[#This Row],[ChurnStatus]]="Cancelled",Table1[[#This Row],[CancellationDate]],TODAY()) -> 44937 | Z14: =IF(AND(Table1[[#This Row],[SubscriptionStart]] <= TODAY(), Table1[[#This Row],[EffectiveEndDate]] >= TODAY()),1,0) -> 0 | AA14: =IF(AND(Table1[[#This Row],[SubscriptionStart]]<=Settings!$A$2,Table1[[#This Row],[EffectiveEndDate]]>=Settings!$A$2),1,0) -> 0 | AB14: =IF(AND(Table1[[#This Row],[SubscriptionStart]]<=Settings!$B$2,Table1[[#This Row],[EffectiveEndDate]]>=Settings!$B$2),1,0) -> 1 | AC14: =IF(AND(Table1[[#This Row],[SubscriptionStart]]<=Settings!$C$2,Table1[[#This Row],[EffectiveEndDate]]>=Settings!$C$2),1,0) -> 1 | AD14: =IF(AND(Table1[[#This Row],[SubscriptionStart]]<=Settings!$D$2,Table1[[#This Row],[EffectiveEndDate]]>=Settings!$D$2),1,0) -> 0 | AE14: =IF(AND(Table1[[#This Row],[SubscriptionStart]]<=Settings!$E$2,Table1[[#This Row],[EffectiveEndDate]]>=Settings!$E$2),1,0) -> 0
A15: CUST0132 | B15: 56 | C15: Male | D15: 44579 | E15: 44609 | F15: =TODAY() - Table1[[#This Row],[SubscriptionStart]] -> 1402 | G15: 1 | H15: Monthly | I15: Premium | J15: {=_xlfn.IFS(Table1[[#This Row],[Tier]]="Basic",10,Table1[[#This Row],[Tier]]="Standard",18,Table1[[#This Row],[Tier]]="Premium",25)} -> 25 | K15: {=_xlfn.IFS(Table1[[#This Row],[SubType]]="Monthly",IF(Table1[[#This Row],[MonthsPaid]]<=12,Table1[[#This Row],[Monthly]]*0.9,Table1[[#This Row],[Monthly]]),Table1[[#This Row],[SubType]]="6-Month",IF(Table1[[#This Row],[MonthsPaid]]<=12,Table1[[#This Row],[Monthly]]*0.75*0.9,Table1[[#This Row],[Monthly]]*0.75),Table1[[#This Row],[SubType]]="12-Month",IF(Table1[[#This Row],[MonthsPaid]]<=12,Table1[[#This Row],[Monthly]]*(2/3)*0.9,Table1[[#This Row],[Monthly]]*(2/3)))} -> 22.5 | L15: {=ROUND(_xlfn.IFS(Table1[[#This Row],[SubType]]="Monthly",(MAX(MIN(Table1[[#This Row],[MonthsPaid]],12)-1,0)*Table1[[#This Row],[Monthly]]*0.9)+(MAX(Table1[[#This Row],[MonthsPaid]]-12,0)*Table1[[#This Row],[Monthly]]),Table1[[#This Row],[SubType]]="6-Month",(MIN(Table1[[#This Row],[MonthsPaid]],12)*Table1[[#This Row],[Monthly]]*0.75*0.9)+(MAX(Table1[[#This Row],[MonthsPaid]]-12,0)*Table1[[#This Row],[Monthly]]*0.75),Table1[[#This Row],[SubType]]="12-Month",(MIN(Table1[[#This Row],[MonthsPaid]],12)*Table1[[#This Row],[Monthly]]*(2/3)*0.9)+(MAX(Table1[[#This Row],[MonthsPaid]]-12,0)*Table1[[#This Row],[Monthly]]*(2/3))),2)} -> 0 | M15: {=_xlfn.IFS(Table1[[#This Row],[Age]]>70,"Elderly",Table1[[#This Row],[Age]]>59,"Senior",Table1[[#This Row],[Age]]>49,"Mature Adult",Table1[[#This Row],[Age]]>25,"Adult",Table1[[#This Row],[Age]]>=18,"Young Adult")} -> Mature Adult | N15: Northern Ireland | O15: None | P15: Other | Q15: {=_xlfn.IFS(Table1[[#This Row],[TotalRevenue]]<100,"Low",Table1[[#This Row],[TotalRevenue]]<300,"Medium",Table1[[#This Row],[TotalRevenue]]<600,"High",TRUE,"Very High")} -> Low | R15: {=_xlfn.IFS(Table1[[#This Row],[Age]]>69,"Elderly",Table1[[#This Row],[Age]]>59,"Mature Adult",Table1[[#This Row],[Age]]>25,"Adult",Table1[[#This Row],[Age]]>18,"Young Adult",Table1[[#This Row],[Age]]>=12,"Teenager")} -> Adult | S15: =IF(Table1[[#This Row],[NextBillingDate]]="","Cancelled",IF(Table1[[#This Row],[CancellationDate]]<>"","Cancelled","Active")) -> Cancelled | T15: {=IF(Table1[[#This Row],[ChurnStatus]]="Cancelled",Table1[[#This Row],[TotalRevenue]],Table1[[#This Row],[TotalRevenue]] + Table1[[#This Row],[Discounted]] * _xlfn.IFS(Table1[[#This Row],[SubType]]="Monthly",1,Table1[[#This Row],[SubType]]="6-Month",6-MOD(Table1[[#This Row],[MonthsPaid]],6),Table1[[#This Row],[SubType]]="12-Month",12-MOD(Table1[[#This Row],[MonthsPaid]],12)))} -> 0 | U15: 44609 | W15: 44609 | X15: 0 | Y15: =IF(Table1[[#This Row],[ChurnStatus]]="Cancelled",Table1[[#This Row],[CancellationDate]],TODAY()) -> 44609 | Z15: =IF(AND(Table1[[#This Row],[SubscriptionStart]] <= TODAY(), Table1[[#This Row],[EffectiveEndDate]] >= TODAY()),1,0) -> 0 | AA15: =IF(AND(Table1[[#This Row],[SubscriptionStart]]<=Settings!$A$2,Table1[[#This Row],[EffectiveEndDate]]>=Settings!$A$2),1,0) -> 0 | AB15: =IF(AND(Table1[[#This Row],[SubscriptionStart]]<=Settings!$B$2,Table1[[#This Row],[EffectiveEndDate]]>=Settings!$B$2),1,0) -> 0 | AC15: =IF(AND(Table1[[#This Row],[SubscriptionStart]]<=Settings!$C$2,Table1[[#This Row],[EffectiveEndDate]]>=Settings!$C$2),1,0) -> 0 | AD15: =IF(AND(Table1[[#This Row],[SubscriptionStart]]<=Settings!$D$2,Table1[[#This Row],[EffectiveEndDate]]>=Settings!$D$2),1,0) -> 0 | AE15: =IF(AND(Table1[[#This Row],[SubscriptionStart]]<=Settings!$E$2,Table1[[#This Row],[EffectiveEndDate]]>=Settings!$E$2),1,0) -> 0
A16: CUST0367 | B16: 72 | C16: Female | D16: 44579 | E16: 44759 | F16: =TODAY() - Table1[[#This Row],[SubscriptionStart]] -> 1402 | G16: 6 | H16: 6-Month | I16: Standard | J16: {=_xlfn.IFS(Table1[[#This Row],[Tier]]="Basic",10,Table1[[#This Row],[Tier]]="Standard",18,Table1[[#This Row],[Tier]]="Premium",25)} -> 18 | K16: {=_xlfn.IFS(Table1[[#This Row],[SubType]]="Monthly",IF(Table1[[#This Row],[MonthsPaid]]<=12,Table1[[#This Row],[Monthly]]*0.9,Table1[[#This Row],[Monthly]]),Table1[[#This Row],[SubType]]="6-Month",IF(Table1[[#This Row],[MonthsPaid]]<=12,Table1[[#This Row],[Monthly]]*0.75*0.9,Table1[[#This Row],[Monthly]]*0.75),Table1[[#This Row],[SubType]]="12-Month",IF(Table1[[#This Row],[MonthsPaid]]<=12,Table1[[#This Row],[Monthly]]*(2/3)*0.9,Table1[[#This Row],[Monthly]]*(2/3)))} -> 12.15 | L16: {=ROUND(_xlfn.IFS(Table1[[#This Row],[SubType]]="Monthly",(MAX(MIN(Table1[[#This Row],[MonthsPaid]],12)-1,0)*Table1[[#This Row],[Monthly]]*0.9)+(MAX(Table1[[#This Row],[MonthsPaid]]-12,0)*Table1[[#This Row],[Monthly]]),Table1[[#This Row],[SubType]]="6-Month",(MIN(Table1[[#This Row],[MonthsPaid]],12)*Table1[[#This Row],[Monthly]]*0.75*0.9)+(MAX(Table1[[#This Row],[MonthsPaid]]-12,0)*Table1[[#This Row],[Monthly]]*0.75),Table1[[#This Row],[SubType]]="12-Month",(MIN(Table1[[#This Row],[MonthsPaid]],12)*Table1[[#This Row],[Monthly]]*(2/3)*0.9)+(MAX(Table1[[#This Row],[MonthsPaid]]-12,0)*Table1[[#This Row],[Monthly]]*(2/3))),2)} -> 72.9 | M16: {=_xlfn.IFS(Table1[[#This Row],[Age]]>70,"Elderly",Table1[[#This Row],[Age]]>59,"Senior",Table1[[#This Row],[Age]]>49,"Mature Adult",Table1[[#This Row],[Age]]>25,"Adult",Table1[[#This Row],[Age]]>=18,"Young Adult")} -> Elderly | N16: England | O16: Search Engine | P16: Too Expensive | Q16: {=_xlfn.IFS(Table1[[#This Row],[TotalRevenue]]<100,"Low",Table1[[#This Row],[TotalRevenue]]<300,"Medium",Table1[[#This Row],[TotalRevenue]]<600,"High",TRUE,"Very High")} -> Low | R16: {=_xlfn.IFS(Table1[[#This Row],[Age]]>69,"Elderly",Table1[[#This Row],[Age]]>59,"Mature Adult",Table1[[#This Row],[Age]]>25,"Adult",Table1[[#This Row],[Age]]>18,"Young Adult",Table1[[#This Row],[Age]]>=12,"Teenager")} -> Elderly | S16: =IF(Table1[[#This Row],[NextBillingDate]]="","Cancelled",IF(Table1[[#This Row],[CancellationDate]]<>"","Cancelled","Active")) -> Cancelled | T16: {=IF(Table1[[#This Row],[ChurnStatus]]="Cancelled",Table1[[#This Row],[TotalRevenue]],Table1[[#This Row],[TotalRevenue]] + Table1[[#This Row],[Discounted]] * _xlfn.IFS(Table1[[#This Row],[SubType]]="Monthly",1,Table1[[#This Row],[SubType]]="6-Month",6-MOD(Table1[[#This Row],[MonthsPaid]],6),Table1[[#This Row],[SubType]]="12-Month",12-MOD(Table1[[#This Row],[MonthsPaid]],12)))} -> 72.9 | U16: 44759 | W16: 44759 | X16: 0 | Y16: =IF(Table1[[#This Row],[ChurnStatus]]="Cancelled",Table1[[#This Row],[CancellationDate]],TODAY()) -> 44759 | Z16: =IF(AND(Table1[[#This Row],[SubscriptionStart]] <= TODAY(), Table1[[#This Row],[EffectiveEndDate]] >= TODAY()),1,0) -> 0 | AA16: =IF(AND(Table1[[#This Row],[SubscriptionStart]]<=Settings!$A$2,Table1[[#This Row],[EffectiveEndDate]]>=Settings!$A$2),1,0) -> 0 | AB16: =IF(AND(Table1[[#This Row],[SubscriptionStart]]<=Settings!$B$2,Table1[[#This Row],[EffectiveEndDate]]>=Settings!$B$2),1,0) -> 1 | AC16: =IF(AND(Table1[[#This Row],[SubscriptionStart]]<=Settings!$C$2,Table1[[#This Row],[EffectiveEndDate]]>=Settings!$C$2),1,0) -> 0 | AD16: =IF(AND(Table1[[#This Row],[SubscriptionStart]]<=Settings!$D$2,Table1[[#This Row],[EffectiveEndDate]]>=Settings!$D$2),1,0) -> 0 | AE16: =IF(AND(Table1[[#This Row],[SubscriptionStart]]<=Settings!$E$2,Table1[[#This Row],[EffectiveEndDate]]>=Settings!$E$2),1,0) -> 0
A17: CUST0300 | B17: 44 | C17: Male | D17: 44580 | E17: 44610 | F17: =TODAY() - Table1[[#This Row],[SubscriptionStart]] -> 1401 | G17: 1 | H17: Monthly | I17: Standard | J17: {=_xlfn.IFS(Table1[[#This Row],[Tier]]="Basic",10,Table1[[#This Row],[Tier]]="Standard",18,Table1[[#This Row],[Tier]]="Premium",25)} -> 18 | K17: {=_xlfn.IFS(Table1[[#This Row],[SubType]]="Monthly",IF(Table1[[#This Row],[MonthsPaid]]<=12,Table1[[#This Row],[Monthly]]*0.9,Table1[[#This Row],[Monthly]]),Table1[[#This Row],[SubType]]="6-Month",IF(Table1[[#This Row],[MonthsPaid]]<=12,Table1[[#This Row],[Monthly]]*0.75*0.9,Table1[[#This Row],[Monthly]]*0.75),Table1[[#This Row],[SubType]]="12-Month",IF(Table1[[#This Row],[MonthsPaid]]<=12,Table1[[#This Row],[Monthly]]*(2/3)*0.9,Table1[[#This Row],[Monthly]]*(2/3)))} -> 16.2 | L17: {=ROUND(_xlfn.IFS(Table1[[#This Row],[SubType]]="Monthly",(MAX(MIN(Table1[[#This Row],[MonthsPaid]],12)-1,0)*Table1[[#This Row],[Monthly]]*0.9)+(MAX(Table1[[#This Row],[MonthsPaid]]-12,0)*Table1[[#This Row],[Monthly]]),Table1[[#This Row],[SubType]]="6-Month",(MIN(Table1[[#This Row],[MonthsPaid]],12)*Table1[[#This Row],[Monthly]]*0.75*0.9)+(MAX(Table1[[#This Row],[MonthsPaid]]-12,0)*Table1[[#This Row],[Monthly]]*0.75),Table1[[#This Row],[SubType]]="12-Month",(MIN(Table1[[#This Row],[MonthsPaid]],12)*Table1[[#This Row],[Monthly]]*(2/3)*0.9)+(MAX(Table1[[#This Row],[MonthsPaid]]-12,0)*Table1[[#This Row],[Monthly]]*(2/3))),2)} -> 0 | M17: {=_xlfn.IFS(Table1[[#This Row],[Age]]>70,"Elderly",Table1[[#This Row],[Age]]>59,"Senior",Table1[[#This Row],[Age]]>49,"Mature Adult",Table1[[#This Row],[Age]]>25,"Adult",Table1[[#This Row],[Age]]>=18,"Young Adult")} -> Adult | N17: Wales | O17: Email Campaign | P17: Switched Service | Q17: {=_xlfn.IFS(Table1[[#This Row],[TotalRevenue]]<100,"Low",Table1[[#This Row],[TotalRevenue]]<300,"Medium",Table1[[#This Row],[TotalRevenue]]<600,"High",TRUE,"Very High")} -> Low | R17: {=_xlfn.IFS(Table1[[#This Row],[Age]]>69,"Elderly",Table1[[#This Row],[Age]]>59,"Mature Adult",Table1[[#This Row],[Age]]>25,"Adult",Table1[[#This Row],[Age]]>18,"Young Adult",Table1[[#This Row],[Age]]>=12,"Teenager")} -> Adult | S17: =IF(Table1[[#This Row],[NextBillingDate]]="","Cancelled",IF(Table1[[#This Row],[CancellationDate]]<>"","Cancelled","Active")) -> Cancelled | T17: {=IF(Table1[[#This Row],[ChurnStatus]]="Cancelled",Table1[[#This Row],[TotalRevenue]],Table1[[#This Row],[TotalRevenue]] + Table1[[#This Row],[Discounted]] * _xlfn.IFS(Table1[[#This Row],[SubType]]="Monthly",1,Table1[[#This Row],[SubType]]="6-Month",6-MOD(Table1[[#This Row],[MonthsPaid]],6),Table1[[#This Row],[SubType]]="12-Month",12-MOD(Table1[[#This Row],[MonthsPaid]],12)))} -> 0 | U17: 44610 | W17: 44610 | X17: 0 | Y17: =IF(Table1[[#This Row],[ChurnStatus]]="Cancelled",Table1[[#This Row],[CancellationDate]],TODAY()) -> 44610 | Z17: =IF(AND(Table1[[#This Row],[SubscriptionStart]] <= TODAY(), Table1[[#This Row],[EffectiveEndDate]] >= TODAY()),1,0) -> 0 | AA17: =IF(AND(Table1[[#This Row],[SubscriptionStart]]<=Settings!$A$2,Table1[[#This Row],[EffectiveEndDate]]>=Settings!$A$2),1,0) -> 0 | AB17: =IF(AND(Table1[[#This Row],[SubscriptionStart]]<=Settings!$B$2,Table1[[#This Row],[EffectiveEndDate]]>=Settings!$B$2),1,0) -> 0 | AC17: =IF(AND(Table1[[#This Row],[SubscriptionStart]]<=Settings!$C$2,Table1[[#This Row],[EffectiveEndDate]]>=Settings!$C$2),1,0) -> 0 | AD17: =IF(AND(Table1[[#This Row],[SubscriptionStart]]<=Settings!$D$2,Table1[[#This Row],[EffectiveEndDate]]>=Settings!$D$2),1,0) -> 0 | AE17: =IF(AND(Table1[[#This Row],[SubscriptionStart]]<=Settings!$E$2,Table1[[#This Row],[EffectiveEndDate]]>=Settings!$E$2),1,0) -> 0
